






















































































































 90%|█████████ | 119/132 [33:01<03:36, 16.65s/it]
Traceback (most recent call last):
  File "/var/folders/_s/sgnns_xx60vdrf8dbqgsl7400000gn/T/ipykernel_24647/1303088829.py", line 26, in <module>
    response = client.chat.completions.create(
  File "/Users/lihongxuan/opt/anaconda3/lib/python3.9/site-packages/openai/_utils/_utils.py", line 271, in wrapper
    return func(*args, **kwargs)
  File "/Users/lihongxuan/opt/anaconda3/lib/python3.9/site-packages/openai/resources/chat/completions.py", line 659, in create
    return self._post(
  File "/Users/lihongxuan/opt/anaconda3/lib/python3.9/site-packages/openai/_base_client.py", line 1200, in post
    return cast(ResponseT, self.request(cast_to, opts, stream=stream, stream_cls=stream_cls))
  File "/Users/lihongxuan/opt/anaconda3/lib/python3.9/site-packages/openai/_base_client.py", line 889, in request
    return self._request(
  File "/Users/lihongxuan/opt/anaconda3/lib/python3.9/site-packages/openai/_base_client.py", line 980, in _request
    raise self._make_status_error_from_response(err.response) from None
openai.AuthenticationError: Error code: 401 - {'error': {'message': 'Incorrect API key provided: sk-3BOJX***************************************j6k5. You can find your API key at https://platform.openai.com/account/api-keys.', 'type': 'invalid_request_error', 'param': None, 'code': 'invalid_api_key'}}